Workbook

Sheet Dashboard
A1: Client Plan Dashboard
A2: Change the yellow levers on the Assumptions sheet; everything updates.
A4: Key output | B4: Value
A5: Selected portfolio | B5: =Assumptions!B18 -> Balanced
A6: Inflation-protection (TIPS) sleeve | B6: =Assumptions!B17 -> 0.05
A7: Net expected return (after fee) | B7: =Projection!H2 -> 0.0462875
A8: Portfolio volatility | B8: =INDEX(Scenarios!H5:H13,Scenarios!B15) -> 0.09612178
A9: Balance at retirement ($) | B9: =INDEX(Projection!H6:H62,Assumptions!B5-Assumptions!B4) -> 1269240.7
A10: Ending balance at plan-to age ($) | B10: =Projection!H62 -> 604113.93
A11: Money lasts to age | B11: =IF(COUNTIF(Projection!H6:H62,"<0")=0,"Beyond "&Assumptions!B6,Assumptions!B6-COUNTIF(Projection!H6:H62,"<0")+1) -> Beyond 92
A13: Best place for the next dollar | B13: ='Account Comparison'!B31 -> 401(k) with employer match
A14: Practice: extra 3-year revenue (data-driven) | B14: ='Practice ROI'!D38 -> 80776.685

Sheet Assumptions
A1: Retirement Portfolio Stress Test Model
A2: Blue = input you can change · Black = formula · Green = link to another sheet · Yellow = key lever. Illustrative assumptions only, not investment advice.
A3: Client profile | B3: Value | C3: Note
A4: Current age | B4: 35 | C4: Example client
A5: Retirement age | B5: 65
A6: Plan-to age | B6: 92 | C6: Projection sheet rows sized for ages 36-92
A7: Current savings ($) | B7: 50000
A8: Annual contribution, year 1 ($) | B8: 12000 | C8: e.g. 401(k) + IRA
A9: Contribution growth (%/yr) | B9: 0.03 | C9: Raises over time
A10: Inflation (%/yr) | B10: 0.025 | C10: Long-run assumption
A11: Retirement spending need (today's $/yr) | B11: 50000
A12: Social Security estimate (today's $/yr) | B12: 24000 | C12: Assumed to start at retirement
A13: Advisory fee (%/yr) | B13: 0.01 | C13: Typical AUM fee
A15: Scenario levers | B15: Value | C15: Note
A16: Model portfolio (1=Conservative, 2=Balanced, 3=Growth) | B16: 2 | C16: Change to see a different portfolio
A17: Inflation-protection (TIPS) sleeve (%) | B17: 0.05 | C17: Carved pro-rata from the core mix
A18: Selected portfolio name | B18: =INDEX($E$21:$G$21,1,$B$16) -> Balanced
A20: Asset class | B20: Example ETF | C20: Expected return | D20: Volatility | E20: Conservative | F20: Balanced | G20: Growth
A21: Base weights -> | E21: Conservative | F21: Balanced | G21: Growth
A22: US stocks | B22: VTI | C22: 0.07 | D22: 0.16 | E22: 0.3 | F22: 0.45 | G22: 0.6
A23: International stocks | B23: VXUS | C23: 0.065 | D23: 0.18 | E23: 0.1 | F23: 0.15 | G23: 0.25
A24: US bonds | B24: BND | C24: 0.04 | D24: 0.06 | E24: 0.6 | F24: 0.4 | G24: 0.15
A25: Inflation-protected bonds (TIPS) | B25: SCHP | C25: 0.038 | D25: 0.055 | E25: 0 | F25: 0 | G25: 0
A26: Total | E26: =SUM(E22:E25) -> 1 | F26: =SUM(F22:F25) -> 1 | G26: =SUM(G22:G25) -> 1
A28: Correlation | B28: US stocks | C28: Intl stocks | D28: US bonds | E28: TIPS
A29: US stocks | B29: 1 | C29: 0.8 | D29: 0.1 | E29: 0.1
A30: Intl stocks | B30: 0.8 | C30: 1 | D30: 0.1 | E30: 0.1
A31: US bonds | B31: 0.1 | C31: 0.1 | D31: 1 | E31: 0.7
A32: TIPS | B32: 0.1 | C32: 0.1 | D32: 0.7 | E32: 1
A34: Covariance | B34: US stocks | C34: Intl stocks | D34: US bonds | E34: TIPS
A35: US stocks | B35: =$D$22*$D$22*B29 -> 0.0256 | C35: =$D$22*$D$23*C29 -> 0.02304 | D35: =$D$22*$D$24*D29 -> 0.00096 | E35: =$D$22*$D$25*E29 -> 0.00088
A36: Intl stocks | B36: =$D$23*$D$22*B30 -> 0.02304 | C36: =$D$23*$D$23*C30 -> 0.0324 | D36: =$D$23*$D$24*D30 -> 0.00108 | E36: =$D$23*$D$25*E30 -> 0.00099
A37: US bonds | B37: =$D$24*$D$22*B31 -> 0.00096 | C37: =$D$24*$D$23*C31 -> 0.00108 | D37: =$D$24*$D$24*D31 -> 0.0036 | E37: =$D$24*$D$25*E31 -> 0.00231
A38: TIPS | B38: =$D$25*$D$22*B32 -> 0.00088 | C38: =$D$25*$D$23*C32 -> 0.00099 | D38: =$D$25*$D$24*D32 -> 0.00231 | E38: =$D$25*$D$25*E32 -> 0.003025
A39: Covariance = vol(i) x vol(j) x correlation(i,j)

Sheet Scenarios
A1: Scenario Comparison: 3 Portfolios x 3 TIPS Sleeves
A2: Closed-form outcomes; the Projection sheet shows the selected case year by year. Bad-luck case = approx. 10th-percentile annualized return: net return - 1.28 x volatility / SQRT(years to retirement).
A4: Portfolio | B4: TIPS % | C4: US stocks | D4: Intl stocks | E4: US bonds | F4: TIPS | G4: Expected return | H4: Volatility | I4: Net return (after fee) | J4: Balance at retirement ($) | K4: Ending balance at plan-to age ($) | L4: Funded? | M4: Bad-luck net return (~10th pct) | N4: Bad-luck ending balance ($) | Q4: Shared inputs
A5: =Assumptions!E21 -> Conservative | B5: 0 | C5: =Assumptions!E22*(1-$B5) -> 0.3 | D5: =Assumptions!E23*(1-$B5) -> 0.1 | E5: =Assumptions!E24*(1-$B5) -> 0.6 | F5: =$B5 -> 0 | G5: =C5*Assumptions!$C$22+D5*Assumptions!$C$23+E5*Assumptions!$C$24+F5*Assumptions!$C$25 -> 0.0515 | H5: =SQRT(C5*SUMPRODUCT(C5:F5,Assumptions!$B$35:$E$35)+D5*SUMPRODUCT(C5:F5,Assumptions!$B$36:$E$36)+E5*SUMPRODUCT(C5:F5,Assumptions!$B$37:$E$37)+F5*SUMPRODUCT(C5:F5,Assumptions!$B$38:$E$38)) -> 0.076036833 | I5: =G5-Assumptions!$B$13 -> 0.0415 | J5: =Assumptions!$B$7*(1+I5)^$R$5+IF(ABS(I5-Assumptions!$B$9)<0.000001,Assumptions!$B$8*$R$5*(1+I5)^($R$5-1),Assumptions!$B$8*((1+I5)^$R$5-(1+Assumptions!$B$9)^$R$5)/(I5-Assumptions!$B$9)) -> 1170500 | K5: =J5*(1+I5)^$R$6-IF(ABS(I5-Assumptions!$B$10)<0.000001,$R$7*$R$6*(1+I5)^($R$6-1),$R$7*((1+I5)^$R$6-(1+Assumptions!$B$10)^$R$6)/(I5-Assumptions!$B$10)) -> 38437.209 | L5: =IF(K5>=0,"Yes","Shortfall") -> Yes | M5: =I5-1.28*H5/SQRT($R$5) -> 0.023730575 | N5: =(Assumptions!$B$7*(1+M5)^$R$5+IF(ABS(M5-Assumptions!$B$9)<0.000001,Assumptions!$B$8*$R$5*(1+M5)^($R$5-1),Assumptions!$B$8*((1+M5)^$R$5-(1+Assumptions!$B$9)^$R$5)/(M5-Assumptions!$B$9)))*(1+M5)^$R$6-IF(ABS(M5-Assumptions!$B$10)<0.000001,$R$7*$R$6*(1+M5)^($R$6-1),$R$7*((1+M5)^$R$6-(1+Assumptions!$B$10)^$R$6)/(M5-Assumptions!$B$10)) -> -1098509.5 | Q5: Years to retirement (n) | R5: =Assumptions!B5-Assumptions!B4 -> 30
A6: =Assumptions!E21 -> Conservative | B6: 0.05 | C6: =Assumptions!E22*(1-$B6) -> 0.285 | D6: =Assumptions!E23*(1-$B6) -> 0.095 | E6: =Assumptions!E24*(1-$B6) -> 0.57 | F6: =$B6 -> 0.05 | G6: =C6*Assumptions!$C$22+D6*Assumptions!$C$23+E6*Assumptions!$C$24+F6*Assumptions!$C$25 -> 0.050825 | H6: =SQRT(C6*SUMPRODUCT(C6:F6,Assumptions!$B$35:$E$35)+D6*SUMPRODUCT(C6:F6,Assumptions!$B$36:$E$36)+E6*SUMPRODUCT(C6:F6,Assumptions!$B$37:$E$37)+F6*SUMPRODUCT(C6:F6,Assumptions!$B$38:$E$38)) -> 0.073427594 | I6: =G6-Assumptions!$B$13 -> 0.040825 | J6: =Assumptions!$B$7*(1+I6)^$R$5+IF(ABS(I6-Assumptions!$B$9)<0.000001,Assumptions!$B$8*$R$5*(1+I6)^($R$5-1),Assumptions!$B$8*((1+I6)^$R$5-(1+Assumptions!$B$9)^$R$5)/(I6-Assumptions!$B$9)) -> 1157352.7 | K6: =J6*(1+I6)^$R$6-IF(ABS(I6-Assumptions!$B$10)<0.000001,$R$7*$R$6*(1+I6)^($R$6-1),$R$7*((1+I6)^$R$6-(1+Assumptions!$B$10)^$R$6)/(I6-Assumptions!$B$10)) -> -29941.478 | L6: =IF(K6>=0,"Yes","Shortfall") -> Shortfall | M6: =I6-1.28*H6/SQRT($R$5) -> 0.023665342 | N6: =(Assumptions!$B$7*(1+M6)^$R$5+IF(ABS(M6-Assumptions!$B$9)<0.000001,Assumptions!$B$8*$R$5*(1+M6)^($R$5-1),Assumptions!$B$8*((1+M6)^$R$5-(1+Assumptions!$B$9)^$R$5)/(M6-Assumptions!$B$9)))*(1+M6)^$R$6-IF(ABS(M6-Assumptions!$B$10)<0.000001,$R$7*$R$6*(1+M6)^($R$6-1),$R$7*((1+M6)^$R$6-(1+Assumptions!$B$10)^$R$6)/(M6-Assumptions!$B$10)) -> -1100758.6 | Q6: Years in retirement (m) | R6: =Assumptions!B6-Assumptions!B5 -> 27
A7: =Assumptions!E21 -> Conservative | B7: 0.1 | C7: =Assumptions!E22*(1-$B7) -> 0.27 | D7: =Assumptions!E23*(1-$B7) -> 0.09 | E7: =Assumptions!E24*(1-$B7) -> 0.54 | F7: =$B7 -> 0.1 | G7: =C7*Assumptions!$C$22+D7*Assumptions!$C$23+E7*Assumptions!$C$24+F7*Assumptions!$C$25 -> 0.05015 | H7: =SQRT(C7*SUMPRODUCT(C7:F7,Assumptions!$B$35:$E$35)+D7*SUMPRODUCT(C7:F7,Assumptions!$B$36:$E$36)+E7*SUMPRODUCT(C7:F7,Assumptions!$B$37:$E$37)+F7*SUMPRODUCT(C7:F7,Assumptions!$B$38:$E$38)) -> 0.070909562 | I7: =G7-Assumptions!$B$13 -> 0.04015 | J7: =Assumptions!$B$7*(1+I7)^$R$5+IF(ABS(I7-Assumptions!$B$9)<0.000001,Assumptions!$B$8*$R$5*(1+I7)^($R$5-1),Assumptions!$B$8*((1+I7)^$R$5-(1+Assumptions!$B$9)^$R$5)/(I7-Assumptions!$B$9)) -> 1144388.3 | K7: =J7*(1+I7)^$R$6-IF(ABS(I7-Assumptions!$B$10)<0.000001,$R$7*$R$6*(1+I7)^($R$6-1),$R$7*((1+I7)^$R$6-(1+Assumptions!$B$10)^$R$6)/(I7-Assumptions!$B$10)) -> -95775.351 | L7: =IF(K7>=0,"Yes","Shortfall") -> Shortfall | M7: =I7-1.28*H7/SQRT($R$5) -> 0.023578793 | N7: =(Assumptions!$B$7*(1+M7)^$R$5+IF(ABS(M7-Assumptions!$B$9)<0.000001,Assumptions!$B$8*$R$5*(1+M7)^($R$5-1),Assumptions!$B$8*((1+M7)^$R$5-(1+Assumptions!$B$9)^$R$5)/(M7-Assumptions!$B$9)))*(1+M7)^$R$6-IF(ABS(M7-Assumptions!$B$10)<0.000001,$R$7*$R$6*(1+M7)^($R$6-1),$R$7*((1+M7)^$R$6-(1+Assumptions!$B$10)^$R$6)/(M7-Assumptions!$B$10)) -> -1103726.8 | Q7: Net need, first retirement year ($) | R7: =(Assumptions!B11-Assumptions!B12)*(1+Assumptions!B10)^R5 -> 54536.757
A8: =Assumptions!F21 -> Balanced | B8: 0 | C8: =Assumptions!F22*(1-$B8) -> 0.45 | D8: =Assumptions!F23*(1-$B8) -> 0.15 | E8: =Assumptions!F24*(1-$B8) -> 0.4 | F8: =$B8 -> 0 | G8: =C8*Assumptions!$C$22+D8*Assumptions!$C$23+E8*Assumptions!$C$24+F8*Assumptions!$C$25 -> 0.05725 | H8: =SQRT(C8*SUMPRODUCT(C8:F8,Assumptions!$B$35:$E$35)+D8*SUMPRODUCT(C8:F8,Assumptions!$B$36:$E$36)+E8*SUMPRODUCT(C8:F8,Assumptions!$B$37:$E$37)+F8*SUMPRODUCT(C8:F8,Assumptions!$B$38:$E$38)) -> 0.10037231 | I8: =G8-Assumptions!$B$13 -> 0.04725 | J8: =Assumptions!$B$7*(1+I8)^$R$5+IF(ABS(I8-Assumptions!$B$9)<0.000001,Assumptions!$B$8*$R$5*(1+I8)^($R$5-1),Assumptions!$B$8*((1+I8)^$R$5-(1+Assumptions!$B$9)^$R$5)/(I8-Assumptions!$B$9)) -> 1290310.8 | K8: =J8*(1+I8)^$R$6-IF(ABS(I8-Assumptions!$B$10)<0.000001,$R$7*$R$6*(1+I8)^($R$6-1),$R$7*((1+I8)^$R$6-(1+Assumptions!$B$10)^$R$6)/(I8-Assumptions!$B$10)) -> 736760.42 | L8: =IF(K8>=0,"Yes","Shortfall") -> Yes | M8: =I8-1.28*H8/SQRT($R$5) -> 0.023793498 | N8: =(Assumptions!$B$7*(1+M8)^$R$5+IF(ABS(M8-Assumptions!$B$9)<0.000001,Assumptions!$B$8*$R$5*(1+M8)^($R$5-1),Assumptions!$B$8*((1+M8)^$R$5-(1+Assumptions!$B$9)^$R$5)/(M8-Assumptions!$B$9)))*(1+M8)^$R$6-IF(ABS(M8-Assumptions!$B$10)<0.000001,$R$7*$R$6*(1+M8)^($R$6-1),$R$7*((1+M8)^$R$6-(1+Assumptions!$B$10)^$R$6)/(M8-Assumptions!$B$10)) -> -1096330.3
A9: =Assumptions!F21 -> Balanced | B9: 0.05 | C9: =Assumptions!F22*(1-$B9) -> 0.4275 | D9: =Assumptions!F23*(1-$B9) -> 0.1425 | E9: =Assumptions!F24*(1-$B9) -> 0.38 | F9: =$B9 -> 0.05 | G9: =C9*Assumptions!$C$22+D9*Assumptions!$C$23+E9*Assumptions!$C$24+F9*Assumptions!$C$25 -> 0.0562875 | H9: =SQRT(C9*SUMPRODUCT(C9:F9,Assumptions!$B$35:$E$35)+D9*SUMPRODUCT(C9:F9,Assumptions!$B$36:$E$36)+E9*SUMPRODUCT(C9:F9,Assumptions!$B$37:$E$37)+F9*SUMPRODUCT(C9:F9,Assumptions!$B$38:$E$38)) -> 0.09612178 | I9: =G9-Assumptions!$B$13 -> 0.0462875 | J9: =Assumptions!$B$7*(1+I9)^$R$5+IF(ABS(I9-Assumptions!$B$9)<0.000001,Assumptions!$B$8*$R$5*(1+I9)^($R$5-1),Assumptions!$B$8*((1+I9)^$R$5-(1+Assumptions!$B$9)^$R$5)/(I9-Assumptions!$B$9)) -> 1269240.7 | K9: =J9*(1+I9)^$R$6-IF(ABS(I9-Assumptions!$B$10)<0.000001,$R$7*$R$6*(1+I9)^($R$6-1),$R$7*((1+I9)^$R$6-(1+Assumptions!$B$10)^$R$6)/(I9-Assumptions!$B$10)) -> 604113.93 | L9: =IF(K9>=0,"Yes","Shortfall") -> Yes | M9: =I9-1.28*H9/SQRT($R$5) -> 0.023824325 | N9: =(Assumptions!$B$7*(1+M9)^$R$5+IF(ABS(M9-Assumptions!$B$9)<0.000001,Assumptions!$B$8*$R$5*(1+M9)^($R$5-1),Assumptions!$B$8*((1+M9)^$R$5-(1+Assumptions!$B$9)^$R$5)/(M9-Assumptions!$B$9)))*(1+M9)^$R$6-IF(ABS(M9-Assumptions!$B$10)<0.000001,$R$7*$R$6*(1+M9)^($R$6-1),$R$7*((1+M9)^$R$6-(1+Assumptions!$B$10)^$R$6)/(M9-Assumptions!$B$10)) -> -1095259.2
A10: =Assumptions!F21 -> Balanced | B10: 0.1 | C10: =Assumptions!F22*(1-$B10) -> 0.405 | D10: =Assumptions!F23*(1-$B10) -> 0.135 | E10: =Assumptions!F24*(1-$B10) -> 0.36 | F10: =$B10 -> 0.1 | G10: =C10*Assumptions!$C$22+D10*Assumptions!$C$23+E10*Assumptions!$C$24+F10*Assumptions!$C$25 -> 0.055325 | H10: =SQRT(C10*SUMPRODUCT(C10:F10,Assumptions!$B$35:$E$35)+D10*SUMPRODUCT(C10:F10,Assumptions!$B$36:$E$36)+E10*SUMPRODUCT(C10:F10,Assumptions!$B$37:$E$37)+F10*SUMPRODUCT(C10:F10,Assumptions!$B$38:$E$38)) -> 0.091951107 | I10: =G10-Assumptions!$B$13 -> 0.045325 | J10: =Assumptions!$B$7*(1+I10)^$R$5+IF(ABS(I10-Assumptions!$B$9)<0.000001,Assumptions!$B$8*$R$5*(1+I10)^($R$5-1),Assumptions!$B$8*((1+I10)^$R$5-(1+Assumptions!$B$9)^$R$5)/(I10-Assumptions!$B$9)) -> 1248590.1 | K10: =J10*(1+I10)^$R$6-IF(ABS(I10-Assumptions!$B$10)<0.000001,$R$7*$R$6*(1+I10)^($R$6-1),$R$7*((1+I10)^$R$6-(1+Assumptions!$B$10)^$R$6)/(I10-Assumptions!$B$10)) -> 478188.36 | L10: =IF(K10>=0,"Yes","Shortfall") -> Yes | M10: =I10-1.28*H10/SQRT($R$5) -> 0.02383649 | N10: =(Assumptions!$B$7*(1+M10)^$R$5+IF(ABS(M10-Assumptions!$B$9)<0.000001,Assumptions!$B$8*$R$5*(1+M10)^($R$5-1),Assumptions!$B$8*((1+M10)^$R$5-(1+Assumptions!$B$9)^$R$5)/(M10-Assumptions!$B$9)))*(1+M10)^$R$6-IF(ABS(M10-Assumptions!$B$10)<0.000001,$R$7*$R$6*(1+M10)^($R$6-1),$R$7*((1+M10)^$R$6-(1+Assumptions!$B$10)^$R$6)/(M10-Assumptions!$B$10)) -> -1094835.8
A11: =Assumptions!G21 -> Growth | B11: 0 | C11: =Assumptions!G22*(1-$B11) -> 0.6 | D11: =Assumptions!G23*(1-$B11) -> 0.25 | E11: =Assumptions!G24*(1-$B11) -> 0.15 | F11: =$B11 -> 0 | G11: =C11*Assumptions!$C$22+D11*Assumptions!$C$23+E11*Assumptions!$C$24+F11*Assumptions!$C$25 -> 0.06425 | H11: =SQRT(C11*SUMPRODUCT(C11:F11,Assumptions!$B$35:$E$35)+D11*SUMPRODUCT(C11:F11,Assumptions!$B$36:$E$36)+E11*SUMPRODUCT(C11:F11,Assumptions!$B$37:$E$37)+F11*SUMPRODUCT(C11:F11,Assumptions!$B$38:$E$38)) -> 0.13596985 | I11: =G11-Assumptions!$B$13 -> 0.05425 | J11: =Assumptions!$B$7*(1+I11)^$R$5+IF(ABS(I11-Assumptions!$B$9)<0.000001,Assumptions!$B$8*$R$5*(1+I11)^($R$5-1),Assumptions!$B$8*((1+I11)^$R$5-(1+Assumptions!$B$9)^$R$5)/(I11-Assumptions!$B$9)) -> 1457043.1 | K11: =J11*(1+I11)^$R$6-IF(ABS(I11-Assumptions!$B$10)<0.000001,$R$7*$R$6*(1+I11)^($R$6-1),$R$7*((1+I11)^$R$6-(1+Assumptions!$B$10)^$R$6)/(I11-Assumptions!$B$10)) -> 1935142.3 | L11: =IF(K11>=0,"Yes","Shortfall") -> Yes | M11: =I11-1.28*H11/SQRT($R$5) -> 0.022474532 | N11: =(Assumptions!$B$7*(1+M11)^$R$5+IF(ABS(M11-Assumptions!$B$9)<0.000001,Assumptions!$B$8*$R$5*(1+M11)^($R$5-1),Assumptions!$B$8*((1+M11)^$R$5-(1+Assumptions!$B$9)^$R$5)/(M11-Assumptions!$B$9)))*(1+M11)^$R$6-IF(ABS(M11-Assumptions!$B$10)<0.000001,$R$7*$R$6*(1+M11)^($R$6-1),$R$7*((1+M11)^$R$6-(1+Assumptions!$B$10)^$R$6)/(M11-Assumptions!$B$10)) -> -1140047.1
A12: =Assumptions!G21 -> Growth | B12: 0.05 | C12: =Assumptions!G22*(1-$B12) -> 0.57 | D12: =Assumptions!G23*(1-$B12) -> 0.2375 | E12: =Assumptions!G24*(1-$B12) -> 0.1425 | F12: =$B12 -> 0.05 | G12: =C12*Assumptions!$C$22+D12*Assumptions!$C$23+E12*Assumptions!$C$24+F12*Assumptions!$C$25 -> 0.0629375 | H12: =SQRT(C12*SUMPRODUCT(C12:F12,Assumptions!$B$35:$E$35)+D12*SUMPRODUCT(C12:F12,Assumptions!$B$36:$E$36)+E12*SUMPRODUCT(C12:F12,Assumptions!$B$37:$E$37)+F12*SUMPRODUCT(C12:F12,Assumptions!$B$38:$E$38)) -> 0.12961247 | I12: =G12-Assumptions!$B$13 -> 0.0529375 | J12: =Assumptions!$B$7*(1+I12)^$R$5+IF(ABS(I12-Assumptions!$B$9)<0.000001,Assumptions!$B$8*$R$5*(1+I12)^($R$5-1),Assumptions!$B$8*((1+I12)^$R$5-(1+Assumptions!$B$9)^$R$5)/(I12-Assumptions!$B$9)) -> 1423882.7 | K12: =J12*(1+I12)^$R$6-IF(ABS(I12-Assumptions!$B$10)<0.000001,$R$7*$R$6*(1+I12)^($R$6-1),$R$7*((1+I12)^$R$6-(1+Assumptions!$B$10)^$R$6)/(I12-Assumptions!$B$10)) -> 1675718.5 | L12: =IF(K12>=0,"Yes","Shortfall") -> Yes | M12: =I12-1.28*H12/SQRT($R$5) -> 0.02264772 | N12: =(Assumptions!$B$7*(1+M12)^$R$5+IF(ABS(M12-Assumptions!$B$9)<0.000001,Assumptions!$B$8*$R$5*(1+M12)^($R$5-1),Assumptions!$B$8*((1+M12)^$R$5-(1+Assumptions!$B$9)^$R$5)/(M12-Assumptions!$B$9)))*(1+M12)^$R$6-IF(ABS(M12-Assumptions!$B$10)<0.000001,$R$7*$R$6*(1+M12)^($R$6-1),$R$7*((1+M12)^$R$6-(1+Assumptions!$B$10)^$R$6)/(M12-Assumptions!$B$10)) -> -1134537.7
A13: =Assumptions!G21 -> Growth | B13: 0.1 | C13: =Assumptions!G22*(1-$B13) -> 0.54 | D13: =Assumptions!G23*(1-$B13) -> 0.225 | E13: =Assumptions!G24*(1-$B13) -> 0.135 | F13: =$B13 -> 0.1 | G13: =C13*Assumptions!$C$22+D13*Assumptions!$C$23+E13*Assumptions!$C$24+F13*Assumptions!$C$25 -> 0.061625 | H13: =SQRT(C13*SUMPRODUCT(C13:F13,Assumptions!$B$35:$E$35)+D13*SUMPRODUCT(C13:F13,Assumptions!$B$36:$E$36)+E13*SUMPRODUCT(C13:F13,Assumptions!$B$37:$E$37)+F13*SUMPRODUCT(C13:F13,Assumptions!$B$38:$E$38)) -> 0.123318 | I13: =G13-Assumptions!$B$13 -> 0.051625 | J13: =Assumptions!$B$7*(1+I13)^$R$5+IF(ABS(I13-Assumptions!$B$9)<0.000001,Assumptions!$B$8*$R$5*(1+I13)^($R$5-1),Assumptions!$B$8*((1+I13)^$R$5-(1+Assumptions!$B$9)^$R$5)/(I13-Assumptions!$B$9)) -> 1391626.7 | K13: =J13*(1+I13)^$R$6-IF(ABS(I13-Assumptions!$B$10)<0.000001,$R$7*$R$6*(1+I13)^($R$6-1),$R$7*((1+I13)^$R$6-(1+Assumptions!$B$10)^$R$6)/(I13-Assumptions!$B$10)) -> 1433429.2 | L13: =IF(K13>=0,"Yes","Shortfall") -> Yes | M13: =I13-1.28*H13/SQRT($R$5) -> 0.022806206 | N13: =(Assumptions!$B$7*(1+M13)^$R$5+IF(ABS(M13-Assumptions!$B$9)<0.000001,Assumptions!$B$8*$R$5*(1+M13)^($R$5-1),Assumptions!$B$8*((1+M13)^$R$5-(1+Assumptions!$B$9)^$R$5)/(M13-Assumptions!$B$9)))*(1+M13)^$R$6-IF(ABS(M13-Assumptions!$B$10)<0.000001,$R$7*$R$6*(1+M13)^($R$6-1),$R$7*((1+M13)^$R$6-(1+Assumptions!$B$10)^$R$6)/(M13-Assumptions!$B$10)) -> -1129435.8
A15: Selected scenario row | B15: =(Assumptions!B16-1)*3+MATCH(Assumptions!B17,B5:B7,0) -> 5 | C15: TIPS % lever must be 0%, 5% or 10% to match a row here; Projection works for any %.

Sheet Projection
A1: Year-by-Year Projection (selected scenario)
A2: Selected portfolio: | B2: =Assumptions!B18 -> Balanced | D2: TIPS %: | E2: =Assumptions!B17 -> 0.05 | G2: Net return: | H2: =SUMPRODUCT(INDEX(Assumptions!$E$22:$G$24,0,Assumptions!$B$16),Assumptions!$C$22:$C$24)*(1-Assumptions!$B$17)+Assumptions!$B$17*Assumptions!$C$25-Assumptions!$B$13 -> 0.0462875
G3: Net need yr 1 of retirement: | H3: =Scenarios!R7 -> 54536.757
A5: Year | B5: Age | C5: Phase | D5: Start balance ($) | E5: Contribution ($) | F5: Withdrawal ($) | G5: Investment growth ($) | H5: End balance ($)
A6: 1 | B6: =Assumptions!$B$4+A6 -> 36 | C6: =IF(B6<=Assumptions!$B$5,"Accumulation","Retirement") -> Accumulation | D6: =Assumptions!B7 -> 50000 | E6: =IF(B6<=Assumptions!$B$5,Assumptions!$B$8*(1+Assumptions!$B$9)^(A6-1),0) -> 12000 | F6: =IF(B6>Assumptions!$B$5,$H$3*(1+Assumptions!$B$10)^(B6-Assumptions!$B$5-1),0) -> 0 | G6: =D6*$H$2 -> 2314.375 | H6: =D6+G6+E6-F6 -> 64314.375
A7: =A6+1 -> 2 | B7: =Assumptions!$B$4+A7 -> 37 | C7: =IF(B7<=Assumptions!$B$5,"Accumulation","Retirement") -> Accumulation | D7: =H6 -> 64314.375 | E7: =IF(B7<=Assumptions!$B$5,Assumptions!$B$8*(1+Assumptions!$B$9)^(A7-1),0) -> 12360 | F7: =IF(B7>Assumptions!$B$5,$H$3*(1+Assumptions!$B$10)^(B7-Assumptions!$B$5-1),0) -> 0 | G7: =D7*$H$2 -> 2976.9516 | H7: =D7+G7+E7-F7 -> 79651.327
A8: =A7+1 -> 3 | B8: =Assumptions!$B$4+A8 -> 38 | C8: =IF(B8<=Assumptions!$B$5,"Accumulation","Retirement") -> Accumulation | D8: =H7 -> 79651.327 | E8: =IF(B8<=Assumptions!$B$5,Assumptions!$B$8*(1+Assumptions!$B$9)^(A8-1),0) -> 12730.8 | F8: =IF(B8>Assumptions!$B$5,$H$3*(1+Assumptions!$B$10)^(B8-Assumptions!$B$5-1),0) -> 0 | G8: =D8*$H$2 -> 3686.8608 | H8: =D8+G8+E8-F8 -> 96068.987
A9: =A8+1 -> 4 | B9: =Assumptions!$B$4+A9 -> 39 | C9: =IF(B9<=Assumptions!$B$5,"Accumulation","Retirement") -> Accumulation | D9: =H8 -> 96068.987 | E9: =IF(B9<=Assumptions!$B$5,Assumptions!$B$8*(1+Assumptions!$B$9)^(A9-1),0) -> 13112.724 | F9: =IF(B9>Assumptions!$B$5,$H$3*(1+Assumptions!$B$10)^(B9-Assumptions!$B$5-1),0) -> 0 | G9: =D9*$H$2 -> 4446.7933 | H9: =D9+G9+E9-F9 -> 113628.5
A10: =A9+1 -> 5 | B10: =Assumptions!$B$4+A10 -> 40 | C10: =IF(B10<=Assumptions!$B$5,"Accumulation","Retirement") -> Accumulation | D10: =H9 -> 113628.5 | E10: =IF(B10<=Assumptions!$B$5,Assumptions!$B$8*(1+Assumptions!$B$9)^(A10-1),0) -> 13506.106 | F10: =IF(B10>Assumptions!$B$5,$H$3*(1+Assumptions!$B$10)^(B10-Assumptions!$B$5-1),0) -> 0 | G10: =D10*$H$2 -> 5259.5794 | H10: =D10+G10+E10-F10 -> 132394.19
A11: =A10+1 -> 6 | B11: =Assumptions!$B$4+A11 -> 41 | C11: =IF(B11<=Assumptions!$B$5,"Accumulation","Retirement") -> Accumulation | D11: =H10 -> 132394.19 | E11: =IF(B11<=Assumptions!$B$5,Assumptions!$B$8*(1+Assumptions!$B$9)^(A11-1),0) -> 13911.289 | F11: =IF(B11>Assumptions!$B$5,$H$3*(1+Assumptions!$B$10)^(B11-Assumptions!$B$5-1),0) -> 0 | G11: =D11*$H$2 -> 6128.1961 | H11: =D11+G11+E11-F11 -> 152433.67
A12: =A11+1 -> 7 | B12: =Assumptions!$B$4+A12 -> 42 | C12: =IF(B12<=Assumptions!$B$5,"Accumulation","Retirement") -> Accumulation | D12: =H11 -> 152433.67 | E12: =IF(B12<=Assumptions!$B$5,Assumptions!$B$8*(1+Assumptions!$B$9)^(A12-1),0) -> 14328.628 | F12: =IF(B12>Assumptions!$B$5,$H$3*(1+Assumptions!$B$10)^(B12-Assumptions!$B$5-1),0) -> 0 | G12: =D12*$H$2 -> 7055.7737 | H12: =D12+G12+E12-F12 -> 173818.08
A13: =A12+1 -> 8 | B13: =Assumptions!$B$4+A13 -> 43 | C13: =IF(B13<=Assumptions!$B$5,"Accumulation","Retirement") -> Accumulation | D13: =H12 -> 173818.08 | E13: =IF(B13<=Assumptions!$B$5,Assumptions!$B$8*(1+Assumptions!$B$9)^(A13-1),0) -> 14758.486 | F13: =IF(B13>Assumptions!$B$5,$H$3*(1+Assumptions!$B$10)^(B13-Assumptions!$B$5-1),0) -> 0 | G13: =D13*$H$2 -> 8045.6042 | H13: =D13+G13+E13-F13 -> 196622.17
A14: =A13+1 -> 9 | B14: =Assumptions!$B$4+A14 -> 44 | C14: =IF(B14<=Assumptions!$B$5,"Accumulation","Retirement") -> Accumulation | D14: =H13 -> 196622.17 | E14: =IF(B14<=Assumptions!$B$5,Assumptions!$B$8*(1+Assumptions!$B$9)^(A14-1),0) -> 15201.241 | F14: =IF(B14>Assumptions!$B$5,$H$3*(1+Assumptions!$B$10)^(B14-Assumptions!$B$5-1),0) -> 0 | G14: =D14*$H$2 -> 9101.1485 | H14: =D14+G14+E14-F14 -> 220924.56
A15: =A14+1 -> 10 | B15: =Assumptions!$B$4+A15 -> 45 | C15: =IF(B15<=Assumptions!$B$5,"Accumulation","Retirement") -> Accumulation | D15: =H14 -> 220924.56 | E15: =IF(B15<=Assumptions!$B$5,Assumptions!$B$8*(1+Assumptions!$B$9)^(A15-1),0) -> 15657.278 | F15: =IF(B15>Assumptions!$B$5,$H$3*(1+Assumptions!$B$10)^(B15-Assumptions!$B$5-1),0) -> 0 | G15: =D15*$H$2 -> 10226.045 | H15: =D15+G15+E15-F15 -> 246807.88
A16: =A15+1 -> 11 | B16: =Assumptions!$B$4+A16 -> 46 | C16: =IF(B16<=Assumptions!$B$5,"Accumulation","Retirement") -> Accumulation | D16: =H15 -> 246807.88 | E16: =IF(B16<=Assumptions!$B$5,Assumptions!$B$8*(1+Assumptions!$B$9)^(A16-1),0) -> 16126.997 | F16: =IF(B16>Assumptions!$B$5,$H$3*(1+Assumptions!$B$10)^(B16-Assumptions!$B$5-1),0) -> 0 | G16: =D16*$H$2 -> 11424.12 | H16: =D16+G16+E16-F16 -> 274359
A17: =A16+1 -> 12 | B17: =Assumptions!$B$4+A17 -> 47 | C17: =IF(B17<=Assumptions!$B$5,"Accumulation","Retirement") -> Accumulation | D17: =H16 -> 274359 | E17: =IF(B17<=Assumptions!$B$5,Assumptions!$B$8*(1+Assumptions!$B$9)^(A17-1),0) -> 16610.806 | F17: =IF(B17>Assumptions!$B$5,$H$3*(1+Assumptions!$B$10)^(B17-Assumptions!$B$5-1),0) -> 0 | G17: =D17*$H$2 -> 12699.392 | H17: =D17+G17+E17-F17 -> 303669.19
A18: =A17+1 -> 13 | B18: =Assumptions!$B$4+A18 -> 48 | C18: =IF(B18<=Assumptions!$B$5,"Accumulation","Retirement") -> Accumulation | D18: =H17 -> 303669.19 | E18: =IF(B18<=Assumptions!$B$5,Assumptions!$B$8*(1+Assumptions!$B$9)^(A18-1),0) -> 17109.131 | F18: =IF(B18>Assumptions!$B$5,$H$3*(1+Assumptions!$B$10)^(B18-Assumptions!$B$5-1),0) -> 0 | G18: =D18*$H$2 -> 14056.088 | H18: =D18+G18+E18-F18 -> 334834.41
... A62: =A61+1 -> 57 | B62: =Assumptions!$B$4+A62 -> 92 | C62: =IF(B62<=Assumptions!$B$5,"Accumulation","Retirement") -> Retirement | D62: =H61 -> 676439.06 | E62: =IF(B62<=Assumptions!$B$5,Assumptions!$B$8*(1+Assumptions!$B$9)^(A62-1),0) -> 0 | F62: =IF(B62>Assumptions!$B$5,$H$3*(1+Assumptions!$B$10)^(B62-Assumptions!$B$5-1),0) -> 103635.8 | G62: =D62*$H$2 -> 31310.673 | H62: =D62+G62+E62-F62 -> 604113.93

Sheet Account Comparison
A1: Account Comparison: Where Should the Next Dollar Go?
A2: Same pre-tax income goes into each account type each year. Compares after-tax value at retirement. Texas has no state income tax, so federal rates only.
A4: Tax & account inputs | B4: Value | C4: Note
A5: Annual pre-tax income set aside, year 1 ($) | B5: 7500 | C5: Equals the 2026 IRA limit ($7,500); 401(k) limit is $24,500 (IRS, Nov 2025)
A6: Current marginal tax rate (%) | B6: 0.22 | C6: Federal bracket while working
A7: Retirement tax rate on withdrawals (%) | B7: 0.12 | C7: Key lever: lower income in retirement
A8: Long-term capital gains rate (%) | B8: 0.15 | C8: Applies to taxable account gains
A9: Taxable account tax drag (%/yr) | B9: 0.005 | C9: Yearly tax on dividends and distributions
A10: Salary, year 1 ($) | B10: 75000 | C10: Needed for employer match
A11: Employer match rate (%) | B11: 0.5 | C11: 50 cents per dollar...
A12: Match cap (% of salary) | B12: 0.06 | C12: ...on the first 6% of salary
A14: Linked from model | B14: Value | C14: Note
A15: Years of saving (n) | B15: =Assumptions!B5-Assumptions!B4 -> 30 | C15: Retirement age - current age
A16: Net return, selected portfolio (r) | B16: =Projection!H2 -> 0.0462875 | C16: From the stress-test model
A17: Contribution growth (g) | B17: =Assumptions!B9 -> 0.03 | C17: Raises; limits also rise with inflation
A19: Growth factors | B19: Value | C19: Note
A20: Tax-free growth factor (FV of $1/yr growing at g) | B20: =IF(ABS(B16-B17)<0.000001,B15*(1+B16)^(B15-1),((1+B16)^B15-(1+B17)^B15)/(B16-B17)) -> 89.577335 | C20: Growing-annuity formula, end-of-year contributions
A21: Taxable growth factor (return less tax drag) | B21: =IF(ABS((B16-B9)-B17)<0.000001,B15*(1+B16-B9)^(B15-1),((1+B16-B9)^B15-(1+B17)^B15)/((B16-B9)-B17)) -> 83.169918
A22: Cost-basis factor (sum of contributions) | B22: =IF(B17=0,B15,((1+B17)^B15-1)/B17) -> 47.575416
A23: Employer match, year 1 ($) | B23: =B11*MIN(B5,B12*B10) -> 2250
A25: Account | B25: Tax treatment | C25: Invested, year 1 ($) | D25: Balance at retirement ($) | E25: Tax due on withdrawal ($) | F25: After-tax value ($) | G25: vs taxable ($)
A26: Taxable brokerage | B26: Taxed now; gains taxed yearly and at sale | C26: =B5*(1-B6) -> 5850 | D26: =C26*B21 -> 486544.02 | E26: =B8*(D26-C26*B22) -> 31234.176 | F26: =D26-E26 -> 455309.85 | G26: =F26-$F$26 -> 0
A27: Traditional IRA | B27: Tax break now; withdrawals taxed | C27: =B5 -> 7500 | D27: =C27*B20 -> 671830.01 | E27: =D27*B7 -> 80619.601 | F27: =D27-E27 -> 591210.41 | G27: =F27-$F$26 -> 135900.56
A28: Roth IRA | B28: Taxed now; withdrawals tax-free | C28: =B5*(1-B6) -> 5850 | D28: =C28*B20 -> 524027.41 | E28: =0 -> 0 | F28: =D28-E28 -> 524027.41 | G28: =F28-$F$26 -> 68717.562
A29: 401(k) with employer match | B29: Tax break now; match is free money; withdrawals taxed | C29: =B5+B23 -> 9750 | D29: =C29*B20 -> 873379.01 | E29: =D29*B7 -> 104805.48 | F29: =D29-E29 -> 768573.53 | G29: =F29-$F$26 -> 313263.69
A31: Best choice at these inputs | B31: =INDEX(A26:A29,MATCH(MAX(F26:F29),F26:F29,0)) -> 401(k) with employer match
A32: Best IRA (Traditional vs Roth) | B32: =IF(F27>F28,"Traditional IRA",IF(F28>F27,"Roth IRA","Tie")) -> Traditional IRA
A34: Retirement tax rate | B34: Traditional IRA after-tax ($) | C34: Roth IRA after-tax ($) | D34: Better IRA | E34: Roth advantage ($)
A35: 0.1 | B35: =$D$27*(1-A35) -> 604647.01 | C35: =$F$28 -> 524027.41 | D35: =IF(B35>C35+0.5,"Traditional",IF(C35>B35+0.5,"Roth","Tie")) -> Traditional | E35: =C35-B35 -> -80619.601
A36: 0.12 | B36: =$D$27*(1-A36) -> 591210.41 | C36: =$F$28 -> 524027.41 | D36: =IF(B36>C36+0.5,"Traditional",IF(C36>B36+0.5,"Roth","Tie")) -> Traditional | E36: =C36-B36 -> -67183.001
A37: 0.22 | B37: =$D$27*(1-A37) -> 524027.41 | C37: =$F$28 -> 524027.41 | D37: =IF(B37>C37+0.5,"Traditional",IF(C37>B37+0.5,"Roth","Tie")) -> Tie | E37: =C37-B37 -> 0
A38: 0.24 | B38: =$D$27*(1-A38) -> 510590.81 | C38: =$F$28 -> 524027.41 | D38: =IF(B38>C38+0.5,"Traditional",IF(C38>B38+0.5,"Roth","Tie")) -> Roth | E38: =C38-B38 -> 13436.6
A39: 0.32 | B39: =$D$27*(1-A39) -> 456844.41 | C39: =$F$28 -> 524027.41 | D39: =IF(B39>C39+0.5,"Traditional",IF(C39>B39+0.5,"Roth","Tie")) -> Roth | E39: =C39-B39 -> 67183.001
A40: Rule of thumb the table proves: Traditional wins if your tax rate drops in retirement, Roth wins if it rises, and they tie when it stays the same.

Sheet Business Cash Flow
A1: Business Cash-Flow Model: Example Co. (fictional)
A2: Made-up small business for demonstration. Driver-based: customers x price, less costs. Blue = input, black = formula.
A4: Business inputs | B4: Value | D4: Scenario | E4: Price change | F4: New customers / mo | G4: Churn / mo | H4: Fixed-cost change
A5: Starting cash ($) | B5: 300000 | D5: Base plan | E5: 0 | F5: =$B$8 -> 0.05 | G5: =$B$9 -> 0.02 | H5: 0
A6: Starting customers | B6: 250 | D6: Raise price 10% | E6: 0.1 | F6: =$B$8 -> 0.05 | G6: =$B$9+0.005 -> 0.025 | H6: 0
A7: Monthly price per customer ($) | B7: 150 | D7: Cut fixed costs 10% | E7: 0 | F7: =$B$8 -> 0.05 | G7: =$B$9 -> 0.02 | H7: -0.1
A8: New customers per month (% of base) | B8: 0.05 | D8: Downturn | E8: 0 | F8: 0.01 | G8: 0.04 | H8: 0
A9: Monthly churn (% lost) | B9: 0.02
A10: Cost of service (% of revenue) | B10: 0.25 | D10: Raising price assumes slightly higher churn (+0.5 pt) as some customers leave.
A11: Fixed operating costs per month ($) | B11: 45000
A12: Scenario | B12: Month-24 revenue ($) | C12: Month-24 monthly profit ($) | D12: Ending cash ($) | E12: Cash runs out in month | F12: Breakeven month
A13: Base plan | B13: =C44 -> 76229.779 | C13: =E44 -> 12172.334 | D13: =F44 -> 217291.81 | E13: =IF(MIN(G21:G44)=999,"Not within 24",MIN(G21:G44)) -> Not within 24 | F13: =IF(MIN(H21:H44)=999,"Not within 24",MIN(H21:H44)) -> 16
A14: Raise price 10% | B14: =J44 -> 74609.945 | C14: =L44 -> 10957.459 | D14: =M44 -> 245818.32 | E14: =IF(MIN(N21:N44)=999,"Not within 24",MIN(N21:N44)) -> Not within 24 | F14: =IF(MIN(O21:O44)=999,"Not within 24",MIN(O21:O44)) -> 16
A15: Cut fixed costs 10% | B15: =Q44 -> 76229.779 | C15: =S44 -> 16672.334 | D15: =T44 -> 325291.81 | E15: =IF(MIN(U21:U44)=999,"Not within 24",MIN(U21:U44)) -> Not within 24 | F15: =IF(MIN(V21:V44)=999,"Not within 24",MIN(V21:V44)) -> 13
A16: Downturn | B16: =X44 -> 18053.146 | C16: =Z44 -> -31460.141 | D16: =AA44 -> -308413.79 | E16: =IF(MIN(AB21:AB44)=999,"Not within 24",MIN(AB21:AB44)) -> 14 | F16: =IF(MIN(AC21:AC44)=999,"Not within 24",MIN(AC21:AC44)) -> Not within 24
A18: Flag columns (neg / BE) mark the first month cash goes negative or profit turns positive (999 = never).
A19: Monthly projection | B19: Base plan | I19: Raise price 10% | P19: Cut fixed costs 10% | W19: Downturn
A20: Month | B20: Customers | C20: Revenue ($) | D20: Costs ($) | E20: Profit / loss ($) | F20: Cash ($) | G20: neg flag | H20: BE flag | I20: Customers | J20: Revenue ($) | K20: Costs ($) | L20: Profit / loss ($) | M20: Cash ($) | N20: neg flag | O20: BE flag | P20: Customers | Q20: Revenue ($) | R20: Costs ($) | S20: Profit / loss ($) | T20: Cash ($) | U20: neg flag | V20: BE flag | W20: Customers | X20: Revenue ($) | Y20: Costs ($) | Z20: Profit / loss ($) | AA20: Cash ($) | AB20: neg flag | AC20: BE flag
A21: 1 | B21: =$B$6*(1+$F$5-$G$5) -> 257.5 | C21: =B21*$B$7*(1+$E$5) -> 38625 | D21: =C21*$B$10+$B$11*(1+$H$5) -> 54656.25 | E21: =C21-D21 -> -16031.25 | F21: =$B$5+E21 -> 283968.75 | G21: =IF(F21<0,$A21,999) -> 999 | H21: =IF(E21>=0,$A21,999) -> 999 | I21: =$B$6*(1+$F$6-$G$6) -> 256.25 | J21: =I21*$B$7*(1+$E$6) -> 42281.25 | K21: =J21*$B$10+$B$11*(1+$H$6) -> 55570.312 | L21: =J21-K21 -> -13289.062 | M21: =$B$5+L21 -> 286710.94 | N21: =IF(M21<0,$A21,999) -> 999 | O21: =IF(L21>=0,$A21,999) -> 999 | P21: =$B$6*(1+$F$7-$G$7) -> 257.5 | Q21: =P21*$B$7*(1+$E$7) -> 38625 | R21: =Q21*$B$10+$B$11*(1+$H$7) -> 50156.25 | S21: =Q21-R21 -> -11531.25 | T21: =$B$5+S21 -> 288468.75 | U21: =IF(T21<0,$A21,999) -> 999 | V21: =IF(S21>=0,$A21,999) -> 999 | W21: =$B$6*(1+$F$8-$G$8) -> 242.5 | X21: =W21*$B$7*(1+$E$8) -> 36375 | Y21: =X21*$B$10+$B$11*(1+$H$8) -> 54093.75 | Z21: =X21-Y21 -> -17718.75 | AA21: =$B$5+Z21 -> 282281.25 | AB21: =IF(AA21<0,$A21,999) -> 999 | AC21: =IF(Z21>=0,$A21,999) -> 999
A22: 2 | B22: =B21*(1+$F$5-$G$5) -> 265.225 | C22: =B22*$B$7*(1+$E$5) -> 39783.75 | D22: =C22*$B$10+$B$11*(1+$H$5) -> 54945.938 | E22: =C22-D22 -> -15162.188 | F22: =F21+E22 -> 268806.56 | G22: =IF(F22<0,$A22,999) -> 999 | H22: =IF(E22>=0,$A22,999) -> 999 | I22: =I21*(1+$F$6-$G$6) -> 262.65625 | J22: =I22*$B$7*(1+$E$6) -> 43338.281 | K22: =J22*$B$10+$B$11*(1+$H$6) -> 55834.57 | L22: =J22-K22 -> -12496.289 | M22: =M21+L22 -> 274214.65 | N22: =IF(M22<0,$A22,999) -> 999 | O22: =IF(L22>=0,$A22,999) -> 999 | P22: =P21*(1+$F$7-$G$7) -> 265.225 | Q22: =P22*$B$7*(1+$E$7) -> 39783.75 | R22: =Q22*$B$10+$B$11*(1+$H$7) -> 50445.938 | S22: =Q22-R22 -> -10662.188 | T22: =T21+S22 -> 277806.56 | U22: =IF(T22<0,$A22,999) -> 999 | V22: =IF(S22>=0,$A22,999) -> 999 | W22: =W21*(1+$F$8-$G$8) -> 235.225 | X22: =W22*$B$7*(1+$E$8) -> 35283.75 | Y22: =X22*$B$10+$B$11*(1+$H$8) -> 53820.938 | Z22: =X22-Y22 -> -18537.188 | AA22: =AA21+Z22 -> 263744.06 | AB22: =IF(AA22<0,$A22,999) -> 999 | AC22: =IF(Z22>=0,$A22,999) -> 999
A23: 3 | B23: =B22*(1+$F$5-$G$5) -> 273.18175 | C23: =B23*$B$7*(1+$E$5) -> 40977.262 | D23: =C23*$B$10+$B$11*(1+$H$5) -> 55244.316 | E23: =C23-D23 -> -14267.053 | F23: =F22+E23 -> 254539.51 | G23: =IF(F23<0,$A23,999) -> 999 | H23: =IF(E23>=0,$A23,999) -> 999 | I23: =I22*(1+$F$6-$G$6) -> 269.22266 | J23: =I23*$B$7*(1+$E$6) -> 44421.738 | K23: =J23*$B$10+$B$11*(1+$H$6) -> 56105.435 | L23: =J23-K23 -> -11683.696 | M23: =M22+L23 -> 262530.95 | N23: =IF(M23<0,$A23,999) -> 999 | O23: =IF(L23>=0,$A23,999) -> 999 | P23: =P22*(1+$F$7-$G$7) -> 273.18175 | Q23: =P23*$B$7*(1+$E$7) -> 40977.262 | R23: =Q23*$B$10+$B$11*(1+$H$7) -> 50744.316 | S23: =Q23-R23 -> -9767.0531 | T23: =T22+S23 -> 268039.51 | U23: =IF(T23<0,$A23,999) -> 999 | V23: =IF(S23>=0,$A23,999) -> 999 | W23: =W22*(1+$F$8-$G$8) -> 228.16825 | X23: =W23*$B$7*(1+$E$8) -> 34225.238 | Y23: =X23*$B$10+$B$11*(1+$H$8) -> 53556.309 | Z23: =X23-Y23 -> -19331.072 | AA23: =AA22+Z23 -> 244412.99 | AB23: =IF(AA23<0,$A23,999) -> 999 | AC23: =IF(Z23>=0,$A23,999) -> 999
A24: 4 | B24: =B23*(1+$F$5-$G$5) -> 281.3772 | C24: =B24*$B$7*(1+$E$5) -> 42206.58 | D24: =C24*$B$10+$B$11*(1+$H$5) -> 55551.645 | E24: =C24-D24 -> -13345.065 | F24: =F23+E24 -> 241194.44 | G24: =IF(F24<0,$A24,999) -> 999 | H24: =IF(E24>=0,$A24,999) -> 999 | I24: =I23*(1+$F$6-$G$6) -> 275.95322 | J24: =I24*$B$7*(1+$E$6) -> 45532.282 | K24: =J24*$B$10+$B$11*(1+$H$6) -> 56383.07 | L24: =J24-K24 -> -10850.789 | M24: =M23+L24 -> 251680.16 | N24: =IF(M24<0,$A24,999) -> 999 | O24: =IF(L24>=0,$A24,999) -> 999 | P24: =P23*(1+$F$7-$G$7) -> 281.3772 | Q24: =P24*$B$7*(1+$E$7) -> 42206.58 | R24: =Q24*$B$10+$B$11*(1+$H$7) -> 51051.645 | S24: =Q24-R24 -> -8845.0647 | T24: =T23+S24 -> 259194.44 | U24: =IF(T24<0,$A24,999) -> 999 | V24: =IF(S24>=0,$A24,999) -> 999 | W24: =W23*(1+$F$8-$G$8) -> 221.3232 | X24: =W24*$B$7*(1+$E$8) -> 33198.48 | Y24: =X24*$B$10+$B$11*(1+$H$8) -> 53299.62 | Z24: =X24-Y24 -> -20101.14 | AA24: =AA23+Z24 -> 224311.85 | AB24: =IF(AA24<0,$A24,999) -> 999 | AC24: =IF(Z24>=0,$A24,999) -> 999
A25: 5 | B25: =B24*(1+$F$5-$G$5) -> 289.81852 | C25: =B25*$B$7*(1+$E$5) -> 43472.778 | D25: =C25*$B$10+$B$11*(1+$H$5) -> 55868.194 | E25: =C25-D25 -> -12395.417 | F25: =F24+E25 -> 228799.03 | G25: =IF(F25<0,$A25,999) -> 999 | H25: =IF(E25>=0,$A25,999) -> 999 | I25: =I24*(1+$F$6-$G$6) -> 282.85205 | J25: =I25*$B$7*(1+$E$6) -> 46670.589 | K25: =J25*$B$10+$B$11*(1+$H$6) -> 56667.647 | L25: =J25-K25 -> -9997.0584 | M25: =M24+L25 -> 241683.11 | N25: =IF(M25<0,$A25,999) -> 999 | O25: =IF(L25>=0,$A25,999) -> 999 | P25: =P24*(1+$F$7-$G$7) -> 289.81852 | Q25: =P25*$B$7*(1+$E$7) -> 43472.778 | R25: =Q25*$B$10+$B$11*(1+$H$7) -> 51368.194 | S25: =Q25-R25 -> -7895.4167 | T25: =T24+S25 -> 251299.03 | U25: =IF(T25<0,$A25,999) -> 999 | V25: =IF(S25>=0,$A25,999) -> 999 | W25: =W24*(1+$F$8-$G$8) -> 214.68351 | X25: =W25*$B$7*(1+$E$8) -> 32202.526 | Y25: =X25*$B$10+$B$11*(1+$H$8) -> 53050.631 | Z25: =X25-Y25 -> -20848.106 | AA25: =AA24+Z25 -> 203463.75 | AB25: =IF(AA25<0,$A25,999) -> 999 | AC25: =IF(Z25>=0,$A25,999) -> 999
A26: 6 | B26: =B25*(1+$F$5-$G$5) -> 298.51307 | C26: =B26*$B$7*(1+$E$5) -> 44776.961 | D26: =C26*$B$10+$B$11*(1+$H$5) -> 56194.24 | E26: =C26-D26 -> -11417.279 | F26: =F25+E26 -> 217381.75 | G26: =IF(F26<0,$A26,999) -> 999 | H26: =IF(E26>=0,$A26,999) -> 999 | I26: =I25*(1+$F$6-$G$6) -> 289.92335 | J26: =I26*$B$7*(1+$E$6) -> 47837.354 | K26: =J26*$B$10+$B$11*(1+$H$6) -> 56959.338 | L26: =J26-K26 -> -9121.9849 | M26: =M25+L26 -> 232561.12 | N26: =IF(M26<0,$A26,999) -> 999 | O26: =IF(L26>=0,$A26,999) -> 999 | P26: =P25*(1+$F$7-$G$7) -> 298.51307 | Q26: =P26*$B$7*(1+$E$7) -> 44776.961 | R26: =Q26*$B$10+$B$11*(1+$H$7) -> 51694.24 | S26: =Q26-R26 -> -6917.2792 | T26: =T25+S26 -> 244381.75 | U26: =IF(T26<0,$A26,999) -> 999 | V26: =IF(S26>=0,$A26,999) -> 999 | W26: =W25*(1+$F$8-$G$8) -> 208.243 | X26: =W26*$B$7*(1+$E$8) -> 31236.45 | Y26: =X26*$B$10+$B$11*(1+$H$8) -> 52809.113 | Z26: =X26-Y26 -> -21572.662 | AA26: =AA25+Z26 -> 181891.08 | AB26: =IF(AA26<0,$A26,999) -> 999 | AC26: =IF(Z26>=0,$A26,999) -> 999
A27: 7 | B27: =B26*(1+$F$5-$G$5) -> 307.46847 | C27: =B27*$B$7*(1+$E$5) -> 46120.27 | D27: =C27*$B$10+$B$11*(1+$H$5) -> 56530.067 | E27: =C27-D27 -> -10409.798 | F27: =F26+E27 -> 206971.95 | G27: =IF(F27<0,$A27,999) -> 999 | H27: =IF(E27>=0,$A27,999) -> 999 | I27: =I26*(1+$F$6-$G$6) -> 297.17144 | J27: =I27*$B$7*(1+$E$6) -> 49033.287 | K27: =J27*$B$10+$B$11*(1+$H$6) -> 57258.322 | L27: =J27-K27 -> -8225.0345 | M27: =M26+L27 -> 224336.09 | N27: =IF(M27<0,$A27,999) -> 999 | O27: =IF(L27>=0,$A27,999) -> 999 | P27: =P26*(1+$F$7-$G$7) -> 307.46847 | Q27: =P27*$B$7*(1+$E$7) -> 46120.27 | R27: =Q27*$B$10+$B$11*(1+$H$7) -> 52030.067 | S27: =Q27-R27 -> -5909.7975 | T27: =T26+S27 -> 238471.95 | U27: =IF(T27<0,$A27,999) -> 999 | V27: =IF(S27>=0,$A27,999) -> 999 | W27: =W26*(1+$F$8-$G$8) -> 201.99571 | X27: =W27*$B$7*(1+$E$8) -> 30299.357 | Y27: =X27*$B$10+$B$11*(1+$H$8) -> 52574.839 | Z27: =X27-Y27 -> -22275.482 | AA27: =AA26+Z27 -> 159615.6 | AB27: =IF(AA27<0,$A27,999) -> 999 | AC27: =IF(Z27>=0,$A27,999) -> 999
A28: 8 | B28: =B27*(1+$F$5-$G$5) -> 316.69252 | C28: =B28*$B$7*(1+$E$5) -> 47503.878 | D28: =C28*$B$10+$B$11*(1+$H$5) -> 56875.97 | E28: =C28-D28 -> -9372.0915 | F28: =F27+E28 -> 197599.86 | G28: =IF(F28<0,$A28,999) -> 999 | H28: =IF(E28>=0,$A28,999) -> 999 | I28: =I27*(1+$F$6-$G$6) -> 304.60072 | J28: =I28*$B$7*(1+$E$6) -> 50259.12 | K28: =J28*$B$10+$B$11*(1+$H$6) -> 57564.78 | L28: =J28-K28 -> -7305.6604 | M28: =M27+L28 -> 217030.43 | N28: =IF(M28<0,$A28,999) -> 999 | O28: =IF(L28>=0,$A28,999) -> 999 | P28: =P27*(1+$F$7-$G$7) -> 316.69252 | Q28: =P28*$B$7*(1+$E$7) -> 47503.878 | R28: =Q28*$B$10+$B$11*(1+$H$7) -> 52375.97 | S28: =Q28-R28 -> -4872.0915 | T28: =T27+S28 -> 233599.86 | U28: =IF(T28<0,$A28,999) -> 999 | V28: =IF(S28>=0,$A28,999) -> 999 | W28: =W27*(1+$F$8-$G$8) -> 195.93584 | X28: =W28*$B$7*(1+$E$8) -> 29390.376 | Y28: =X28*$B$10+$B$11*(1+$H$8) -> 52347.594 | Z28: =X28-Y28 -> -22957.218 | AA28: =AA27+Z28 -> 136658.38 | AB28: =IF(AA28<0,$A28,999) -> 999 | AC28: =IF(Z28>=0,$A28,999) -> 999
A29: 9 | B29: =B28*(1+$F$5-$G$5) -> 326.1933 | C29: =B29*$B$7*(1+$E$5) -> 48928.994 | D29: =C29*$B$10+$B$11*(1+$H$5) -> 57232.249 | E29: =C29-D29 -> -8303.2542 | F29: =F28+E29 -> 189296.61 | G29: =IF(F29<0,$A29,999) -> 999 | H29: =IF(E29>=0,$A29,999) -> 999 | I29: =I28*(1+$F$6-$G$6) -> 312.21574 | J29: =I29*$B$7*(1+$E$6) -> 51515.598 | K29: =J29*$B$10+$B$11*(1+$H$6) -> 57878.899 | L29: =J29-K29 -> -6363.3019 | M29: =M28+L29 -> 210667.12 | N29: =IF(M29<0,$A29,999) -> 999 | O29: =IF(L29>=0,$A29,999) -> 999 | P29: =P28*(1+$F$7-$G$7) -> 326.1933 | Q29: =P29*$B$7*(1+$E$7) -> 48928.994 | R29: =Q29*$B$10+$B$11*(1+$H$7) -> 52732.249 | S29: =Q29-R29 -> -3803.2542 | T29: =T28+S29 -> 229796.61 | U29: =IF(T29<0,$A29,999) -> 999 | V29: =IF(S29>=0,$A29,999) -> 999 | W29: =W28*(1+$F$8-$G$8) -> 190.05776 | X29: =W29*$B$7*(1+$E$8) -> 28508.665 | Y29: =X29*$B$10+$B$11*(1+$H$8) -> 52127.166 | Z29: =X29-Y29 -> -23618.501 | AA29: =AA28+Z29 -> 113039.88 | AB29: =IF(AA29<0,$A29,999) -> 999 | AC29: =IF(Z29>=0,$A29,999) -> 999
A30: 10 | B30: =B29*(1+$F$5-$G$5) -> 335.97909 | C30: =B30*$B$7*(1+$E$5) -> 50396.864 | D30: =C30*$B$10+$B$11*(1+$H$5) -> 57599.216 | E30: =C30-D30 -> -7202.3518 | F30: =F29+E30 -> 182094.25 | G30: =IF(F30<0,$A30,999) -> 999 | H30: =IF(E30>=0,$A30,999) -> 999 | I30: =I29*(1+$F$6-$G$6) -> 320.02114 | J30: =I30*$B$7*(1+$E$6) -> 52803.487 | K30: =J30*$B$10+$B$11*(1+$H$6) -> 58200.872 | L30: =J30-K30 -> -5397.3844 | M30: =M29+L30 -> 205269.74 | N30: =IF(M30<0,$A30,999) -> 999 | O30: =IF(L30>=0,$A30,999) -> 999 | P30: =P29*(1+$F$7-$G$7) -> 335.97909 | Q30: =P30*$B$7*(1+$E$7) -> 50396.864 | R30: =Q30*$B$10+$B$11*(1+$H$7) -> 53099.216 | S30: =Q30-R30 -> -2702.3518 | T30: =T29+S30 -> 227094.25 | U30: =IF(T30<0,$A30,999) -> 999 | V30: =IF(S30>=0,$A30,999) -> 999 | W30: =W29*(1+$F$8-$G$8) -> 184.35603 | X30: =W30*$B$7*(1+$E$8) -> 27653.405 | Y30: =X30*$B$10+$B$11*(1+$H$8) -> 51913.351 | Z30: =X30-Y30 -> -24259.946 | AA30: =AA29+Z30 -> 88779.935 | AB30: =IF(AA30<0,$A30,999) -> 999 | AC30: =IF(Z30>=0,$A30,999) -> 999
A31: 11 | B31: =B30*(1+$F$5-$G$5) -> 346.05847 | C31: =B31*$B$7*(1+$E$5) -> 51908.77 | D31: =C31*$B$10+$B$11*(1+$H$5) -> 57977.193 | E31: =C31-D31 -> -6068.4224 | F31: =F30+E31 -> 176025.83 | G31: =IF(F31<0,$A31,999) -> 999 | H31: =IF(E31>=0,$A31,999) -> 999 | I31: =I30*(1+$F$6-$G$6) -> 328.02166 | J31: =I31*$B$7*(1+$E$6) -> 54123.575 | K31: =J31*$B$10+$B$11*(1+$H$6) -> 58530.894 | L31: =J31-K31 -> -4407.319 | M31: =M30+L31 -> 200862.42 | N31: =IF(M31<0,$A31,999) -> 999 | O31: =IF(L31>=0,$A31,999) -> 999 | P31: =P30*(1+$F$7-$G$7) -> 346.05847 | Q31: =P31*$B$7*(1+$E$7) -> 51908.77 | R31: =Q31*$B$10+$B$11*(1+$H$7) -> 53477.193 | S31: =Q31-R31 -> -1568.4224 | T31: =T30+S31 -> 225525.83 | U31: =IF(T31<0,$A31,999) -> 999 | V31: =IF(S31>=0,$A31,999) -> 999 | W31: =W30*(1+$F$8-$G$8) -> 178.82535 | X31: =W31*$B$7*(1+$E$8) -> 26823.803 | Y31: =X31*$B$10+$B$11*(1+$H$8) -> 51705.951 | Z31: =X31-Y31 -> -24882.148 | AA31: =AA30+Z31 -> 63897.787 | AB31: =IF(AA31<0,$A31,999) -> 999 | AC31: =IF(Z31>=0,$A31,999) -> 999
A32: 12 | B32: =B31*(1+$F$5-$G$5) -> 356.44022 | C32: =B32*$B$7*(1+$E$5) -> 53466.033 | D32: =C32*$B$10+$B$11*(1+$H$5) -> 58366.508 | E32: =C32-D32 -> -4900.4751 | F32: =F31+E32 -> 171125.36 | G32: =IF(F32<0,$A32,999) -> 999 | H32: =IF(E32>=0,$A32,999) -> 999 | I32: =I31*(1+$F$6-$G$6) -> 336.22221 | J32: =I32*$B$7*(1+$E$6) -> 55476.664 | K32: =J32*$B$10+$B$11*(1+$H$6) -> 58869.166 | L32: =J32-K32 -> -3392.502 | M32: =M31+L32 -> 197469.92 | N32: =IF(M32<0,$A32,999) -> 999 | O32: =IF(L32>=0,$A32,999) -> 999 | P32: =P31*(1+$F$7-$G$7) -> 356.44022 | Q32: =P32*$B$7*(1+$E$7) -> 53466.033 | R32: =Q32*$B$10+$B$11*(1+$H$7) -> 53866.508 | S32: =Q32-R32 -> -400.47506 | T32: =T31+S32 -> 225125.36 | U32: =IF(T32<0,$A32,999) -> 999 | V32: =IF(S32>=0,$A32,999) -> 999 | W32: =W31*(1+$F$8-$G$8) -> 173.46059 | X32: =W32*$B$7*(1+$E$8) -> 26019.089 | Y32: =X32*$B$10+$B$11*(1+$H$8) -> 51504.772 | Z32: =X32-Y32 -> -25485.684 | AA32: =AA31+Z32 -> 38412.103 | AB32: =IF(AA32<0,$A32,999) -> 999 | AC32: =IF(Z32>=0,$A32,999) -> 999
A33: 13 | B33: =B32*(1+$F$5-$G$5) -> 367.13343 | C33: =B33*$B$7*(1+$E$5) -> 55070.014 | D33: =C33*$B$10+$B$11*(1+$H$5) -> 58767.504 | E33: =C33-D33 -> -3697.4893 | F33: =F32+E33 -> 167427.87 | G33: =IF(F33<0,$A33,999) -> 999 | H33: =IF(E33>=0,$A33,999) -> 999 | I33: =I32*(1+$F$6-$G$6) -> 344.62776 | J33: =I33*$B$7*(1+$E$6) -> 56863.581 | K33: =J33*$B$10+$B$11*(1+$H$6) -> 59215.895 | L33: =J33-K33 -> -2352.3145 | M33: =M32+L33 -> 195117.6 | N33: =IF(M33<0,$A33,999) -> 999 | O33: =IF(L33>=0,$A33,999) -> 999 | P33: =P32*(1+$F$7-$G$7) -> 367.13343 | Q33: =P33*$B$7*(1+$E$7) -> 55070.014 | R33: =Q33*$B$10+$B$11*(1+$H$7) -> 54267.504 | S33: =Q33-R33 -> 802.51069 | T33: =T32+S33 -> 225927.87 | U33: =IF(T33<0,$A33,999) -> 999 | V33: =IF(S33>=0,$A33,999) -> 13 | W33: =W32*(1+$F$8-$G$8) -> 168.25677 | X33: =W33*$B$7*(1+$E$8) -> 25238.516 | Y33: =X33*$B$10+$B$11*(1+$H$8) -> 51309.629 | Z33: =X33-Y33 -> -26071.113 | AA33: =AA32+Z33 -> 12340.99 | AB33: =IF(AA33<0,$A33,999) -> 999 | AC33: =IF(Z33>=0,$A33,999) -> 999
... A44: 24 | B44: =B43*(1+$F$5-$G$5) -> 508.19853 | C44: =B44*$B$7*(1+$E$5) -> 76229.779 | D44: =C44*$B$10+$B$11*(1+$H$5) -> 64057.445 | E44: =C44-D44 -> 12172.334 | F44: =F43+E44 -> 217291.81 | G44: =IF(F44<0,$A44,999) -> 999 | H44: =IF(E44>=0,$A44,999) -> 24 | I44: =I43*(1+$F$6-$G$6) -> 452.18149 | J44: =I44*$B$7*(1+$E$6) -> 74609.945 | K44: =J44*$B$10+$B$11*(1+$H$6) -> 63652.486 | L44: =J44-K44 -> 10957.459 | M44: =M43+L44 -> 245818.32 | N44: =IF(M44<0,$A44,999) -> 999 | O44: =IF(L44>=0,$A44,999) -> 24 | P44: =P43*(1+$F$7-$G$7) -> 508.19853 | Q44: =P44*$B$7*(1+$E$7) -> 76229.779 | R44: =Q44*$B$10+$B$11*(1+$H$7) -> 59557.445 | S44: =Q44-R44 -> 16672.334 | T44: =T43+S44 -> 325291.81 | U44: =IF(T44<0,$A44,999) -> 999 | V44: =IF(S44>=0,$A44,999) -> 24 | W44: =W43*(1+$F$8-$G$8) -> 120.35431 | X44: =W44*$B$7*(1+$E$8) -> 18053.146 | Y44: =X44*$B$10+$B$11*(1+$H$8) -> 49513.286 | Z44: =X44-Y44 -> -31460.141 | AA44: =AA43+Z44 -> -308413.79 | AB44: =IF(AA44<0,$A44,999) -> 24 | AC44: =IF(Z44>=0,$A44,999) -> 999

Sheet Simulation
A1: Monte Carlo Simulation: 1,000 Possible Futures for Example Co.
A2: Each run draws its own underlying growth ~ Normal(5%, 1.5%) and churn ~ Normal(2%, 0.5%), plus 1% month-to-month noise in growth; other inputs as in the base plan. Seed 42. Values are simulation output; re-run business_cashflow.py to refresh.
A4: Simulation result | B4: Value
A5: Runs | B5: 1000
A6: Chance cash stays positive all 24 months | B6: 0.88
A7: Chance of reaching a profitable month | B7: 0.746
A8: Ending cash, bad case (10th percentile) | B8: -13994.256
A9: Ending cash, typical (median) | B9: 221752.53
A10: Ending cash, good case (90th percentile) | B10: 537479.03
A13: Month | B13: 10th pct cash ($) | C13: 25th pct ($) | D13: Median ($) | E13: 75th pct ($) | F13: 90th pct ($)
A14: 1 | B14: 283278.31 | C14: 283606.43 | D14: 283955.05 | E14: 284311.16 | F14: 284624.7
A15: 2 | B15: 266919.35 | C15: 267791.41 | D15: 268752.25 | E15: 269823.99 | F15: 270740.4
A16: 3 | B16: 250824.54 | C16: 252562.77 | D16: 254480.21 | E16: 256519.2 | F16: 258383.14
A17: 4 | B17: 234946.86 | C17: 238015.25 | D17: 241179.77 | E17: 244438.67 | F17: 247743.62
A18: 5 | B18: 219409.88 | C18: 224021.81 | D18: 228913.18 | E18: 233867.23 | F18: 238825.18
A19: 6 | B19: 204445.21 | C19: 210434.57 | D19: 217663.28 | E19: 224675.45 | F19: 231675.71
A20: 7 | B20: 189800.75 | C20: 197573.25 | D20: 207429.07 | E20: 216873.7 | F20: 226280.56
A21: 8 | B21: 175394.38 | C21: 185400.58 | D21: 198286.77 | E21: 210437.2 | F21: 222569.73
A22: 9 | B22: 161205.89 | C22: 173987.94 | D22: 190114.99 | E22: 205470.19 | F22: 221474.03
A23: 10 | B23: 147345.59 | C23: 162832.81 | D23: 183008.33 | E23: 202353.92 | F23: 222276.03
A24: 11 | B24: 133921.03 | C24: 152734.2 | D24: 176953.07 | E24: 200909.27 | F24: 224784.65
A25: 12 | B25: 120608.38 | C25: 143039.21 | D25: 172294.99 | E25: 201467.56 | F25: 230400.89
... A37: 24 | B37: -13994.256 | C37: 82714.143 | D37: 221752.53 | E37: 367996.52 | F37: 537479.03

Sheet Practice ROI
A1: Practice ROI Model: From Planning Conversations to Firm Revenue
A2: Illustrative assumptions; replace with the firm's figures. Blue = input, green = link, yellow = the four inputs the data-driven approach changes.
A4: Input | B4: Standard approach | C4: Data-driven approach | D4: Note
A5: Prospects met per month | B5: 20 | C5: 20 | D5: Seminars, referrals and meetings
A6: Conversion to client (%) | B6: 0.15 | C6: 0.2 | D6: Assumption: stress test + live planner give prospects a clear reason to act
A7: Annual client retention (%) | B7: 0.92 | C7: 0.95 | D7: Assumption: clients who understand their plan stay longer
A8: Average assets per new client ($) | B8: 33000 | C8: 33000 | D8: Increase Consultants averages about $32.9K per client (AdvizorPro)
A9: New contributions per client per year ($) | B9: 6000 | C9: 6000 | D9: Ongoing savings added to managed accounts
A10: Portfolio growth before fee (%) | B10: =Projection!$H$2+Assumptions!$B$13 -> 0.0562875 | C10: =Projection!$H$2+Assumptions!$B$13 -> 0.0562875 | D10: Linked: selected portfolio from the stress-test model
A11: Advisory fee (%/yr) | B11: =Assumptions!$B$13 -> 0.01 | C11: =Assumptions!$B$13 -> 0.01 | D11: Linked from Assumptions
A12: Clients buying an annuity (%) | B12: 0.2 | C12: 0.25 | D12: Assumption: stress test shows when guaranteed income helps
A13: Average annuity premium ($) | B13: 50000 | C13: 50000 | D13: Assumption
A14: Annuity commission (% of premium) | B14: 0.05 | C14: 0.05 | D14: Assumption; varies by product
A15: Clients buying life insurance (%) | B15: 0.25 | C15: 0.3 | D15: Assumption
A16: Average annual life premium ($) | B16: 1500 | C16: 1500 | D16: Assumption
A17: First-year commission (% of premium) | B17: 0.8 | C17: 0.8 | D17: Assumption; varies by carrier
A18: Renewal commission (% of premium) | B18: 0.05 | C18: 0.05 | D18: Assumption
A19: Planner cost per year ($) | B19: 45000 | C19: 45000 | D19: Assumption: base pay plus licensing and tools
A20: Discount rate for client value (%) | B20: 0.08 | C20: 0.08 | D20: Used in the lifetime-value DCF
A22: Metric | B22: Standard Y1 | C22: Standard Y2 | D22: Standard Y3 | E22: Data-driven Y1 | F22: Data-driven Y2 | G22: Data-driven Y3
A23: New clients | B23: =$B$5*12*$B$6 -> 36 | C23: =$B$5*12*$B$6 -> 36 | D23: =$B$5*12*$B$6 -> 36 | E23: =$C$5*12*$C$6 -> 48 | F23: =$C$5*12*$C$6 -> 48 | G23: =$C$5*12*$C$6 -> 48
A24: Clients at year end | B24: =0*$B$7+B23 -> 36 | C24: =B24*$B$7+C23 -> 69.12 | D24: =C24*$B$7+D23 -> 99.5904 | E24: =0*$C$7+E23 -> 48 | F24: =E24*$C$7+F23 -> 93.6 | G24: =F24*$C$7+G23 -> 136.92
A25: Insured clients at year end | B25: =0*$B$7+B23*$B$15 -> 9 | C25: =B25*$B$7+C23*$B$15 -> 17.28 | D25: =C25*$B$7+D23*$B$15 -> 24.8976 | E25: =0*$C$7+E23*$C$15 -> 14.4 | F25: =E25*$C$7+F23*$C$15 -> 28.08 | G25: =F25*$C$7+G23*$C$15 -> 41.076
A26: Assets under management, year end ($) | B26: =0*$B$7*(1+$B$10)+B23*$B$8+B24*$B$9 -> 1404000 | C26: =B26*$B$7*(1+$B$10)+C23*$B$8+C24*$B$9 -> 2967105.4 | D26: =C26*$B$7*(1+$B$10)+D23*$B$8+D24*$B$9 -> 4668929.5 | E26: =0*$C$7*(1+$C$10)+E23*$C$8+E24*$C$9 -> 1872000 | F26: =E26*$C$7*(1+$C$10)+F23*$C$8+F24*$C$9 -> 4024101.7 | G26: =F26*$C$7*(1+$C$10)+G23*$C$8+G24*$C$9 -> 6443597.9
A27: Average AUM during year ($) | B27: =(0+B26)/2 -> 702000 | C27: =(B26+C26)/2 -> 2185552.7 | D27: =(C26+D26)/2 -> 3818017.5 | E27: =(0+E26)/2 -> 936000 | F27: =(E26+F26)/2 -> 2948050.8 | G27: =(F26+G26)/2 -> 5233849.8
A28: Advisory fee revenue ($) | B28: =B27*$B$11 -> 7020 | C28: =C27*$B$11 -> 21855.527 | D28: =D27*$B$11 -> 38180.175 | E28: =E27*$C$11 -> 9360 | F28: =F27*$C$11 -> 29480.508 | G28: =G27*$C$11 -> 52338.498
A29: Annuity commissions ($) | B29: =B23*$B$12*$B$13*$B$14 -> 18000 | C29: =C23*$B$12*$B$13*$B$14 -> 18000 | D29: =D23*$B$12*$B$13*$B$14 -> 18000 | E29: =E23*$C$12*$C$13*$C$14 -> 30000 | F29: =F23*$C$12*$C$13*$C$14 -> 30000 | G29: =G23*$C$12*$C$13*$C$14 -> 30000
A30: Insurance first-year commissions ($) | B30: =B23*$B$15*$B$16*$B$17 -> 10800 | C30: =C23*$B$15*$B$16*$B$17 -> 10800 | D30: =D23*$B$15*$B$16*$B$17 -> 10800 | E30: =E23*$C$15*$C$16*$C$17 -> 17280 | F30: =F23*$C$15*$C$16*$C$17 -> 17280 | G30: =G23*$C$15*$C$16*$C$17 -> 17280
A31: Insurance renewal commissions ($) | B31: =0*$B$7*$B$16*$B$18 -> 0 | C31: =B25*$B$7*$B$16*$B$18 -> 621 | D31: =C25*$B$7*$B$16*$B$18 -> 1192.32 | E31: =0*$C$7*$C$16*$C$18 -> 0 | F31: =E25*$C$7*$C$16*$C$18 -> 1026 | G31: =F25*$C$7*$C$16*$C$18 -> 2000.7
A32: Total revenue ($) | B32: =SUM(B28:B31) -> 35820 | C32: =SUM(C28:C31) -> 51276.527 | D32: =SUM(D28:D31) -> 68172.495 | E32: =SUM(E28:E31) -> 56640 | F32: =SUM(F28:F31) -> 77786.508 | G32: =SUM(G28:G31) -> 101619.2
A33: Planner cost ($) | B33: =$B$19 -> 45000 | C33: =$B$19 -> 45000 | D33: =$B$19 -> 45000 | E33: =$C$19 -> 45000 | F33: =$C$19 -> 45000 | G33: =$C$19 -> 45000
A34: Net contribution to firm ($) | B34: =B32-B33 -> -9180 | C34: =C32-C33 -> 6276.5272 | D34: =D32-D33 -> 23172.495 | E34: =E32-E33 -> 11640 | F34: =F32-F33 -> 32786.508 | G34: =G32-G33 -> 56619.198
A35: Revenue per $1 of planner cost | B35: =IF(B33=0,0,B32/B33) -> 0.796 | C35: =IF(C33=0,0,C32/C33) -> 1.1394784 | D35: =IF(D33=0,0,D32/D33) -> 1.5149443 | E35: =IF(E33=0,0,E32/E33) -> 1.2586667 | F35: =IF(F33=0,0,F32/F33) -> 1.7285891 | G35: =IF(G33=0,0,G32/G33) -> 2.2582044
A37: 3-year summary | B37: Standard | C37: Data-driven | D37: Difference
A38: Total revenue, 3 years ($) | B38: =SUM(B32:D32) -> 155269.02 | C38: =SUM(E32:G32) -> 236045.71 | D38: =C38-B38 -> 80776.685
A39: Net contribution, 3 years ($) | B39: =SUM(B34:D34) -> 20269.022 | C39: =SUM(E34:G34) -> 101045.71 | D39: =C39-B39 -> 80776.685
A40: Clients at end of year 3 | B40: =D24 -> 99.5904 | C40: =G24 -> 136.92 | D40: =C40-B40 -> 37.3296
A41: Assets under management, end of year 3 ($) | B41: =D26 -> 4668929.5 | C41: =G26 -> 6443597.9 | D41: =C41-B41 -> 1774668.4
A42: Revenue per $1 of planner cost, 3 years | B42: =SUM(B32:D32)/SUM(B33:D33) -> 1.1501409 | C42: =SUM(E32:G32)/SUM(E33:G33) -> 1.7484867 | D42: =C42-B42 -> 0.59834581
A43: Data-driven approach changes only conversion, retention, annuity and insurance take-up (yellow cells); everything else is identical, so the difference isolates their effect.
...
